Workbook

Sheet Data Rasio Keuangan
A1: INPUT DATA MENTAH LAPORAN KEUANGAN PT XL AXIATA Tbk (EXCL) & PT SMARTFREN TELECOM Tbk (FREN)
A2: Sumber: Laporan Keuangan Konsolidasian Teraudit | IDX & Investor Relations | Satuan: Rp Miliar
A3: No | B3: Tahun | C3: Kuartal | D3: Keterangan | E3: Total Aset (Rp Miliar) | F3: Aset Lancar (Rp Miliar) | G3: Liabilitas Lancar (Rp Miliar) | H3: Net PP&E (Aset Tetap Bersih) (Rp Miliar) | I3: Short Term Debt (Rp Miliar) | J3: Long Term Debt (Rp Miliar) | K3: Total Ekuitas (Rp Miliar) | L3: EBIT (Rp Miliar) | M3: Pretax Income (Rp Miliar) | N3: Taxes (Rp Miliar) | O3: Laba Bersih (Rp Miliar) | P3: Total Pendapatan (Rp Miliar) | Q3: Periode Original
A4: 1 | B4: 2021 | C4: Q1 | D4: Sebelum Merger | E4: 65930 | F4: 5950 | G4: 19290 | H4: 47100 | I4: 7380 | J4: 24870 | K4: 19470 | L4: 703.55 | M4: 389.44 | N4: -68.92 | O4: 320.51 | P4: 6250 | Q4: Q1'21 Mar 2021
A5: 2 | B5: 2021 | C5: Q2 | D5: Sebelum Merger | E5: 67490 | F5: 5850 | G5: 18810 | H5: 48780 | I5: 7090 | J5: 26900 | K5: 19330 | L5: 873.92 | M5: 452.84 | N5: -57.4 | O5: 395.44 | P5: 6730 | Q5: Q2'21 Jun 2021
A6: 3 | B6: 2021 | C6: Q3 | D6: Sebelum Merger | E6: 68590 | F6: 6610 | G6: 18810 | H6: 49100 | I6: 6870 | J6: 27340 | K6: 19820 | L6: 921.67 | M6: 413.81 | N6: -113.37 | O6: 300.44 | P6: 6830 | Q6: Q3'21 Sep 2021
A7: 4 | B7: 2021 | C7: Q4 | D7: Sebelum Merger | E7: 72750 | F7: 7730 | G7: 20950 | H7: 51910 | I7: 6280 | J7: 27740 | K7: 20090 | L7: 831.46 | M7: 451.41 | N7: -180.01 | O7: 271.4 | P7: 6950 | Q7: Q4'21 Des 2021
A8: 5 | B8: 2022 | C8: Q1 | D8: Sebelum Merger | E8: 71840 | F8: 6200 | G8: 21430 | H8: 52610 | I8: 7890 | J8: 27900 | K8: 20240 | L8: 613.04 | M8: 172.22 | N8: -33.12 | O8: 139.09 | P8: 6740 | Q8: Q1'22 Mar 2022
A9: 6 | B9: 2022 | C9: Q2 | D9: Sebelum Merger | E9: 76420 | F9: 5920 | G9: 22700 | H9: 54010 | I9: 8700 | J9: 31160 | K9: 20340 | L9: 1020 | M9: 555.87 | N9: -77.95 | O9: 475.82 | P9: 7330 | Q9: Q2'22 Jun 2022
A10: 7 | B10: 2022 | C10: Q3 | D10: Sebelum Merger | E10: 81680 | F10: 8960 | G10: 25060 | H10: 56180 | I10: 10520 | J10: 33750 | K10: 20710 | L10: 3.04 | M10: 2.22 | N10: 3.12 | O10: 9.09 | P10: 6740 | Q10: Q3'22 Sep 2022
A11: 8 | B11: 2022 | C11: Q4 | D11: Sebelum Merger | E11: 87280 | F11: 10410 | G11: 26350 | H11: 60470 | I11: 10920 | J11: 33040 | K11: 25770 | L11: 1020 | M11: 555.87 | N11: -77.95 | O11: 475.82 | P11: 7350 | Q11: Q4'22 Des 2022
A12: 9 | B12: 2023 | C12: Q1 | D12: Sebelum Merger | E12: 83730 | F12: 6880 | G12: 24940 | H12: 60170 | I12: 10090 | J12: 30710 | K12: 25970 | L12: 1060 | M12: 465.35 | N12: -93.59 | O12: 366.29 | P12: 7520 | Q12: Q1'23 Mar 2023
A13: 10 | B13: 2023 | C13: Q2 | D13: Sebelum Merger | E13: 83690 | F13: 5770 | G13: 22970 | H13: 61100 | I13: 9650 | J13: 32820 | K13: 25880 | L13: 961.93 | M13: 159.6 | N13: -27.18 | O13: 128.24 | P13: 7550 | Q13: Q2'23 Jun 2023
A14: 11 | B14: 2023 | C14: Q3 | D14: Sebelum Merger | E14: 86100 | F14: 5450 | G14: 21740 | H14: 63410 | I14: 8050 | J14: 36090 | K14: 26250 | L14: 841.37 | M14: 237.78 | N14: -33.6 | O14: 200.89 | P14: 7550 | Q14: Q3'23 Sep 2023
A15: 12 | B15: 2023 | C15: Q4 | D15: Sebelum Merger | E15: 87690 | F15: 7170 | G15: 20170 | H15: 63900 | I15: 6880 | J15: 39040 | K15: 26470 | L15: 1240 | M15: 565.56 | N15: -112.21 | O15: 449.79 | P15: 8220 | Q15: Q4'23 Des 2023
... A23: 20 | B23: 2025 | C23: Q4 | D23: Sesudah Merger | E23: 115220 | F23: 15020 | G23: 30450 | H23: 66980 | I23: 11220 | J23: 51610 | K23: 30010 | L23: -55.15 | M23: -1860 | N23: 258.28 | O23: -1610 | P23: 10490 | Q23: Q4'25 Des 2025
A26: TABULASI DATA KEUANGAN (KOMPONEN TURUNAN UNTUK PERHITUNGAN RASIO)
A27: No | B27: Tahun | C27: Kuartal | D27: Keterangan | E27: Utang Berbunga (Rp Miliar) = Short+Long Debt | F27: Invested Capital (Rp Miliar) = Ekuitas+Utg Berbunga | G27: Tax Rate Efektif (%) = |Taxes|/|Pretax| | H27: NOPAT (Rp Miliar) = EBIT×(1−TaxRate) | I27: Total Aset (ref) | J27: Aset Lancar (ref) | K27: Liabilitas Lancar (ref) | L27: Net PP&E (ref) | M27: Total Ekuitas (ref) | N27: Laba Bersih (ref) | O27: Total Pendapatan (ref)
A28: 1 | B28: 2021 | C28: Q1 | D28: Sebelum Merger | E28: =I4+J4 -> 32250 | F28: =K4+E28 -> 51720 | G28: =(ABS(N4)/ABS(M4))*100 -> 17.697206 | H28: =L4*(1-G28/100) -> 579.04131 | I28: =E4 -> 65930 | J28: =F4 -> 5950 | K28: =G4 -> 19290 | L28: =H4 -> 47100 | M28: =K4 -> 19470 | N28: =O4 -> 320.51 | O28: =P4 -> 6250
A29: 2 | B29: 2021 | C29: Q2 | D29: Sebelum Merger | E29: =I5+J5 -> 33990 | F29: =K5+E29 -> 53320 | G29: =(ABS(N5)/ABS(M5))*100 -> 12.675559 | H29: =L5*(1-G29/100) -> 763.14576 | I29: =E5 -> 67490 | J29: =F5 -> 5850 | K29: =G5 -> 18810 | L29: =H5 -> 48780 | M29: =K5 -> 19330 | N29: =O5 -> 395.44 | O29: =P5 -> 6730
A30: 3 | B30: 2021 | C30: Q3 | D30: Sebelum Merger | E30: =I6+J6 -> 34210 | F30: =K6+E30 -> 54030 | G30: =(ABS(N6)/ABS(M6))*100 -> 27.396631 | H30: =L6*(1-G30/100) -> 669.16347 | I30: =E6 -> 68590 | J30: =F6 -> 6610 | K30: =G6 -> 18810 | L30: =H6 -> 49100 | M30: =K6 -> 19820 | N30: =O6 -> 300.44 | O30: =P6 -> 6830
A31: 4 | B31: 2021 | C31: Q4 | D31: Sebelum Merger | E31: =I7+J7 -> 34020 | F31: =K7+E31 -> 54110 | G31: =(ABS(N7)/ABS(M7))*100 -> 39.877273 | H31: =L7*(1-G31/100) -> 499.89642 | I31: =E7 -> 72750 | J31: =F7 -> 7730 | K31: =G7 -> 20950 | L31: =H7 -> 51910 | M31: =K7 -> 20090 | N31: =O7 -> 271.4 | O31: =P7 -> 6950
A32: 5 | B32: 2022 | C32: Q1 | D32: Sebelum Merger | E32: =I8+J8 -> 35790 | F32: =K8+E32 -> 56030 | G32: =(ABS(N8)/ABS(M8))*100 -> 19.231216 | H32: =L8*(1-G32/100) -> 495.14495 | I32: =E8 -> 71840 | J32: =F8 -> 6200 | K32: =G8 -> 21430 | L32: =H8 -> 52610 | M32: =K8 -> 20240 | N32: =O8 -> 139.09 | O32: =P8 -> 6740
A33: 6 | B33: 2022 | C33: Q2 | D33: Sebelum Merger | E33: =I9+J9 -> 39860 | F33: =K9+E33 -> 60200 | G33: =(ABS(N9)/ABS(M9))*100 -> 14.023063 | H33: =L9*(1-G33/100) -> 876.96476 | I33: =E9 -> 76420 | J33: =F9 -> 5920 | K33: =G9 -> 22700 | L33: =H9 -> 54010 | M33: =K9 -> 20340 | N33: =O9 -> 475.82 | O33: =P9 -> 7330
A34: 7 | B34: 2022 | C34: Q3 | D34: Sebelum Merger | E34: =I10+J10 -> 44270 | F34: =K10+E34 -> 64980 | G34: =(ABS(N10)/ABS(M10))*100 -> 140.54054 | H34: =L10*(1-G34/100) -> -1.2324324 | I34: =E10 -> 81680 | J34: =F10 -> 8960 | K34: =G10 -> 25060 | L34: =H10 -> 56180 | M34: =K10 -> 20710 | N34: =O10 -> 9.09 | O34: =P10 -> 6740
A35: 8 | B35: 2022 | C35: Q4 | D35: Sebelum Merger | E35: =I11+J11 -> 43960 | F35: =K11+E35 -> 69730 | G35: =(ABS(N11)/ABS(M11))*100 -> 14.023063 | H35: =L11*(1-G35/100) -> 876.96476 | I35: =E11 -> 87280 | J35: =F11 -> 10410 | K35: =G11 -> 26350 | L35: =H11 -> 60470 | M35: =K11 -> 25770 | N35: =O11 -> 475.82 | O35: =P11 -> 7350
A36: 9 | B36: 2023 | C36: Q1 | D36: Sebelum Merger | E36: =I12+J12 -> 40800 | F36: =K12+E36 -> 66770 | G36: =(ABS(N12)/ABS(M12))*100 -> 20.111744 | H36: =L12*(1-G36/100) -> 846.81552 | I36: =E12 -> 83730 | J36: =F12 -> 6880 | K36: =G12 -> 24940 | L36: =H12 -> 60170 | M36: =K12 -> 25970 | N36: =O12 -> 366.29 | O36: =P12 -> 7520
A37: 10 | B37: 2023 | C37: Q2 | D37: Sebelum Merger | E37: =I13+J13 -> 42470 | F37: =K13+E37 -> 68350 | G37: =(ABS(N13)/ABS(M13))*100 -> 17.030075 | H37: =L13*(1-G37/100) -> 798.1126 | I37: =E13 -> 83690 | J37: =F13 -> 5770 | K37: =G13 -> 22970 | L37: =H13 -> 61100 | M37: =K13 -> 25880 | N37: =O13 -> 128.24 | O37: =P13 -> 7550
A38: 11 | B38: 2023 | C38: Q3 | D38: Sebelum Merger | E38: =I14+J14 -> 44140 | F38: =K14+E38 -> 70390 | G38: =(ABS(N14)/ABS(M14))*100 -> 14.130709 | H38: =L14*(1-G38/100) -> 722.47845 | I38: =E14 -> 86100 | J38: =F14 -> 5450 | K38: =G14 -> 21740 | L38: =H14 -> 63410 | M38: =K14 -> 26250 | N38: =O14 -> 200.89 | O38: =P14 -> 7550
A39: 12 | B39: 2023 | C39: Q4 | D39: Sebelum Merger | E39: =I15+J15 -> 45920 | F39: =K15+E39 -> 72390 | G39: =(ABS(N15)/ABS(M15))*100 -> 19.840512 | H39: =L15*(1-G39/100) -> 993.97765 | I39: =E15 -> 87690 | J39: =F15 -> 7170 | K39: =G15 -> 20170 | L39: =H15 -> 63900 | M39: =K15 -> 26470 | N39: =O15 -> 449.79 | O39: =P15 -> 8220
... A47: 20 | B47: 2025 | C47: Q4 | D47: Sesudah Merger | E47: =I23+J23 -> 62830 | F47: =K23+E47 -> 92840 | G47: =(ABS(N23)/ABS(M23))*100 -> 13.886022 | H47: =L23*(1-G47/100) -> -47.491859 | I47: =E23 -> 115220 | J47: =F23 -> 15020 | K47: =G23 -> 30450 | L47: =H23 -> 66980 | M47: =K23 -> 30010 | N47: =O23 -> -1610 | O47: =P23 -> 10490
A50: PERHITUNGAN RASIO KEUANGAN PER KUARTAL
E51: ROIC = NOPAT / Inv.Capital × 100 | F51: ROA = Laba Bersih / Total Aset × 100 | G51: ROE = Laba Bersih / Total Ekuitas × 100 | H51: NPM = Laba Bersih / Total Pend. × 100 | I51: DER = Total Hutang / Total Ekuitas × 100 | J51: TDTC = Total Hutang / (Hutang+Ekuitas) × 100 | K51: CR = Aset Lancar / Liab. Lancar | L51: FAT = Total Pend. / Net PP&E
A52: No | B52: Tahun | C52: Kuartal | D52: Keterangan | E52: ROIC | F52: ROA | G52: ROE | H52: NPM | I52: DER | J52: TDTC | K52: CR | L52: FAT
A53: 1 | B53: 2021 | C53: Q1 | D53: Sebelum Merger | E53: 1.1196 | F53: 0.4861 | G53: 1.6462 | H53: 5.1282 | I53: 165.6394 | J53: 62.355 | K53: 0.3084 | L53: 0.1327
A54: 2 | B54: 2021 | C54: Q2 | D54: Sebelum Merger | E54: 1.4313 | F54: 0.5859 | G54: 2.0457 | H54: 5.8758 | I54: 175.8407 | J54: 63.7472 | K54: 0.311 | L54: 0.138
A55: 3 | B55: 2021 | C55: Q3 | D55: Sebelum Merger | E55: 1.2385 | F55: 0.438 | G55: 1.5158 | H55: 4.3988 | I55: 172.6034 | J55: 63.3167 | K55: 0.3514 | L55: 0.1391
A56: 4 | B56: 2021 | C56: Q4 | D56: Sebelum Merger | E56: 0.9239 | F56: 0.3731 | G56: 1.3509 | H56: 3.905 | I56: 169.338 | J56: 62.8719 | K56: 0.369 | L56: 0.1339
A57: 5 | B57: 2022 | C57: Q1 | D57: Sebelum Merger | E57: 0.8837 | F57: 0.1936 | G57: 0.6872 | H57: 2.0636 | I57: 176.8281 | J57: 63.8765 | K57: 0.2893 | L57: 0.1281
A58: 6 | B58: 2022 | C58: Q2 | D58: Sebelum Merger | E58: 1.4568 | F58: 0.6226 | G58: 2.3393 | H58: 6.4914 | I58: 195.9685 | J58: 66.2126 | K58: 0.2608 | L58: 0.1357
...

Sheet Uji Normalitas KS
A1: Uji Normalitas KS - ROIC, seluruh data kuartalan (n = 20)
A2: i | B2: xᵢ (urut) | C2: Fₙ(y⁻) | D2: Fₙ(y) | E2: F₀(y) | F2: |Fₙ(y)-F₀(y)| | G2: |F₀(y)-Fₙ(y⁻)| | I2: μ̂ = | J2: =AVERAGE('Data Rasio Keuangan'!$E$53:$E$72) -> 1.09211
A3: 1 | B3: =SMALL('Data Rasio Keuangan'!$E$53:$E$72,1) -> -0.0512 | C3: =(1-1)/20 -> 0 | D3: =1/20 -> 0.05 | E3: =NORMDIST(B3,$J2,$J3,TRUE()) -> 0.0035593378 | F3: =ABS(D3-E3) -> 0.046440662 | G3: =ABS(E3-C3) -> 0.0035593378 | I3: σ̂ = | J3: =STDEV('Data Rasio Keuangan'!$E$53:$E$72) -> 0.42482632
A4: 2 | B4: =SMALL('Data Rasio Keuangan'!$E$53:$E$72,2) -> -0.0019 | C4: =(2-1)/20 -> 0.05 | D4: =2/20 -> 0.1 | E4: =NORMDIST(B4,$J2,$J3,TRUE()) -> 0.0050092004 | F4: =ABS(D4-E4) -> 0.0949908 | G4: =ABS(E4-C4) -> 0.0449908
A5: 3 | B5: =SMALL('Data Rasio Keuangan'!$E$53:$E$72,3) -> 0.8837 | C5: =(3-1)/20 -> 0.1 | D5: =3/20 -> 0.15 | E5: =NORMDIST(B5,$J2,$J3,TRUE()) -> 0.31186285 | F5: =ABS(D5-E5) -> 0.16186285 | G5: =ABS(E5-C5) -> 0.21186285
A6: 4 | B6: =SMALL('Data Rasio Keuangan'!$E$53:$E$72,4) -> 0.9239 | C6: =(4-1)/20 -> 0.15 | D6: =4/20 -> 0.2 | E6: =NORMDIST(B6,$J2,$J3,TRUE()) -> 0.34607094 | F6: =ABS(D6-E6) -> 0.14607094 | G6: =ABS(E6-C6) -> 0.19607094
A7: 5 | B7: =SMALL('Data Rasio Keuangan'!$E$53:$E$72,5) -> 0.9257 | C7: =(5-1)/20 -> 0.2 | D7: =5/20 -> 0.25 | E7: =NORMDIST(B7,$J2,$J3,TRUE()) -> 0.34763514 | F7: =ABS(D7-E7) -> 0.097635135 | G7: =ABS(E7-C7) -> 0.14763514
A8: 6 | B8: =SMALL('Data Rasio Keuangan'!$E$53:$E$72,6) -> 1.0264 | C8: =(6-1)/20 -> 0.25 | D8: =6/20 -> 0.3 | E8: =NORMDIST(B8,$J2,$J3,TRUE()) -> 0.43853878 | F8: =ABS(D8-E8) -> 0.13853878 | G8: =ABS(E8-C8) -> 0.18853878
A9: 7 | B9: =SMALL('Data Rasio Keuangan'!$E$53:$E$72,7) -> 1.0772 | C9: =(7-1)/20 -> 0.3 | D9: =7/20 -> 0.35 | E9: =NORMDIST(B9,$J2,$J3,TRUE()) -> 0.48600132 | F9: =ABS(D9-E9) -> 0.13600132 | G9: =ABS(E9-C9) -> 0.18600132
A10: 8 | B10: =SMALL('Data Rasio Keuangan'!$E$53:$E$72,8) -> 1.1196 | C10: =(8-1)/20 -> 0.35 | D10: =8/20 -> 0.4 | E10: =NORMDIST(B10,$J2,$J3,TRUE()) -> 0.52579707 | F10: =ABS(D10-E10) -> 0.12579707 | G10: =ABS(E10-C10) -> 0.17579707
A11: 9 | B11: =SMALL('Data Rasio Keuangan'!$E$53:$E$72,9) -> 1.1677 | C11: =(9-1)/20 -> 0.4 | D11: =9/20 -> 0.45 | E11: =NORMDIST(B11,$J2,$J3,TRUE()) -> 0.57061163 | F11: =ABS(D11-E11) -> 0.12061163 | G11: =ABS(E11-C11) -> 0.17061163
A12: 10 | B12: =SMALL('Data Rasio Keuangan'!$E$53:$E$72,10) -> 1.2043 | C12: =(10-1)/20 -> 0.45 | D12: =10/20 -> 0.5 | E12: =NORMDIST(B12,$J2,$J3,TRUE()) -> 0.60414255 | F12: =ABS(D12-E12) -> 0.10414255 | G12: =ABS(E12-C12) -> 0.15414255
A13: 11 | B13: =SMALL('Data Rasio Keuangan'!$E$53:$E$72,11) -> 1.2385 | C13: =(11-1)/20 -> 0.5 | D13: =11/20 -> 0.55 | E13: =NORMDIST(B13,$J2,$J3,TRUE()) -> 0.63479789 | F13: =ABS(D13-E13) -> 0.084797889 | G13: =ABS(E13-C13) -> 0.13479789
A14: 12 | B14: =SMALL('Data Rasio Keuangan'!$E$53:$E$72,12) -> 1.2577 | C14: =(12-1)/20 -> 0.55 | D14: =12/20 -> 0.6 | E14: =NORMDIST(B14,$J2,$J3,TRUE()) -> 0.65165142 | F14: =ABS(D14-E14) -> 0.051651424 | G14: =ABS(E14-C14) -> 0.10165142
A15: 13 | B15: =SMALL('Data Rasio Keuangan'!$E$53:$E$72,13) -> 1.2683 | C15: =(13-1)/20 -> 0.6 | D15: =13/20 -> 0.65 | E15: =NORMDIST(B15,$J2,$J3,TRUE()) -> 0.66083175 | F15: =ABS(D15-E15) -> 0.01083175 | G15: =ABS(E15-C15) -> 0.06083175
A16: 14 | B16: =SMALL('Data Rasio Keuangan'!$E$53:$E$72,14) -> 1.2701 | C16: =(14-1)/20 -> 0.65 | D16: =14/20 -> 0.7 | E16: =NORMDIST(B16,$J2,$J3,TRUE()) -> 0.66238142 | F16: =ABS(D16-E16) -> 0.037618585 | G16: =ABS(E16-C16) -> 0.012381415
A17: 15 | B17: =SMALL('Data Rasio Keuangan'!$E$53:$E$72,15) -> 1.2938 | C17: =(15-1)/20 -> 0.7 | D17: =15/20 -> 0.75 | E17: =NORMDIST(B17,$J2,$J3,TRUE()) -> 0.68252052 | F17: =ABS(D17-E17) -> 0.06747948 | G17: =ABS(E17-C17) -> 0.01747948
A18: 16 | B18: =SMALL('Data Rasio Keuangan'!$E$53:$E$72,16) -> 1.3731 | C18: =(16-1)/20 -> 0.75 | D18: =16/20 -> 0.8 | E18: =NORMDIST(B18,$J2,$J3,TRUE()) -> 0.74582954 | F18: =ABS(D18-E18) -> 0.054170464 | G18: =ABS(E18-C18) -> 0.0041704643
A19: 17 | B19: =SMALL('Data Rasio Keuangan'!$E$53:$E$72,17) -> 1.4239 | C19: =(17-1)/20 -> 0.8 | D19: =17/20 -> 0.85 | E19: =NORMDIST(B19,$J2,$J3,TRUE()) -> 0.7825992 | F19: =ABS(D19-E19) -> 0.067400802 | G19: =ABS(E19-C19) -> 0.017400802
A20: 18 | B20: =SMALL('Data Rasio Keuangan'!$E$53:$E$72,18) -> 1.4313 | C20: =(18-1)/20 -> 0.85 | D20: =18/20 -> 0.9 | E20: =NORMDIST(B20,$J2,$J3,TRUE()) -> 0.78768671 | F20: =ABS(D20-E20) -> 0.11231329 | G20: =ABS(E20-C20) -> 0.062313285
A21: 19 | B21: =SMALL('Data Rasio Keuangan'!$E$53:$E$72,19) -> 1.4568 | C21: =(19-1)/20 -> 0.9 | D21: =19/20 -> 0.95 | E21: =NORMDIST(B21,$J2,$J3,TRUE()) -> 0.80467659 | F21: =ABS(D21-E21) -> 0.14532341 | G21: =ABS(E21-C21) -> 0.095323414
A22: 20 | B22: =SMALL('Data Rasio Keuangan'!$E$53:$E$72,20) -> 1.5533 | C22: =(20-1)/20 -> 0.95 | D22: =20/20 -> 1 | E22: =NORMDIST(B22,$J2,$J3,TRUE()) -> 0.86117124 | F22: =ABS(D22-E22) -> 0.13882876 | G22: =ABS(E22-C22) -> 0.088828757
A23: Dₙ (maks.) | B23: =MAX(F3:G22) -> 0.21186285
A24: D(n=20; α=0,05) kritis | B24: 0.29407 | C24: (Tabel nilai kritis Kolmogorov-Smirnov standar, n=20, α=0,05)
A25: Keputusan | B25: =IF(B23<B24,"Normal (H0 gagal ditolak)","Tidak Normal (H0 ditolak)") -> Normal (H0 gagal ditolak)
A27: Uji Normalitas Kolmogorov-Smirnov — ROA, seluruh data kuartalan (n = 20)
A28: i | B28: xᵢ (urut) | C28: Fₙ(y⁻) | D28: Fₙ(y) | E28: F₀(y) | F28: |Fₙ(y)-F₀(y)| | G28: |F₀(y)-Fₙ(y⁻)| | I28: μ̂ = | J28: =AVERAGE('Data Rasio Keuangan'!$F$53:$F$72) -> 0.309765
A29: 1 | B29: =SMALL('Data Rasio Keuangan'!$F$53:$F$72,1) -> -1.3973 | C29: =(1-1)/20 -> 0 | D29: =1/20 -> 0.05 | E29: =NORMDIST(B29,$J28,$J29,TRUE()) -> 4.2034528e-05 | F29: =ABS(D29-E29) -> 0.049957965 | G29: =ABS(E29-C29) -> 4.2034528e-05 | I29: σ̂ = | J29: =STDEV('Data Rasio Keuangan'!$F$53:$F$72) -> 0.4340922
A30: 2 | B30: =SMALL('Data Rasio Keuangan'!$F$53:$F$72,2) -> 0.0111 | C30: =(2-1)/20 -> 0.05 | D30: =2/20 -> 0.1 | E30: =NORMDIST(B30,$J28,$J29,TRUE()) -> 0.24571945 | F30: =ABS(D30-E30) -> 0.14571945 | G30: =ABS(E30-C30) -> 0.19571945
A31: 3 | B31: =SMALL('Data Rasio Keuangan'!$F$53:$F$72,3) -> 0.1532 | C31: =(3-1)/20 -> 0.1 | D31: =3/20 -> 0.15 | E31: =NORMDIST(B31,$J28,$J29,TRUE()) -> 0.35917224 | F31: =ABS(D31-E31) -> 0.20917224 | G31: =ABS(E31-C31) -> 0.25917224
A32: 4 | B32: =SMALL('Data Rasio Keuangan'!$F$53:$F$72,4) -> 0.1936 | C32: =(4-1)/20 -> 0.15 | D32: =4/20 -> 0.2 | E32: =NORMDIST(B32,$J28,$J29,TRUE()) -> 0.39450191 | F32: =ABS(D32-E32) -> 0.19450191 | G32: =ABS(E32-C32) -> 0.24450191
A33: 5 | B33: =SMALL('Data Rasio Keuangan'!$F$53:$F$72,5) -> 0.2333 | C33: =(5-1)/20 -> 0.2 | D33: =5/20 -> 0.25 | E33: =NORMDIST(B33,$J28,$J29,TRUE()) -> 0.43008836 | F33: =ABS(D33-E33) -> 0.18008836 | G33: =ABS(E33-C33) -> 0.23008836
A34: 6 | B34: =SMALL('Data Rasio Keuangan'!$F$53:$F$72,6) -> 0.2968 | C34: =(6-1)/20 -> 0.25 | D34: =6/20 -> 0.3 | E34: =NORMDIST(B34,$J28,$J29,TRUE()) -> 0.48808659 | F34: =ABS(D34-E34) -> 0.18808659 | G34: =ABS(E34-C34) -> 0.23808659
A35: 7 | B35: =SMALL('Data Rasio Keuangan'!$F$53:$F$72,7) -> 0.3439 | C35: =(7-1)/20 -> 0.3 | D35: =7/20 -> 0.35 | E35: =NORMDIST(B35,$J28,$J29,TRUE()) -> 0.53133867 | F35: =ABS(D35-E35) -> 0.18133867 | G35: =ABS(E35-C35) -> 0.23133867
A36: 8 | B36: =SMALL('Data Rasio Keuangan'!$F$53:$F$72,8) -> 0.3502 | C36: =(8-1)/20 -> 0.35 | D36: =8/20 -> 0.4 | E36: =NORMDIST(B36,$J28,$J29,TRUE()) -> 0.53710717 | F36: =ABS(D36-E36) -> 0.13710717 | G36: =ABS(E36-C36) -> 0.18710717
A37: 9 | B37: =SMALL('Data Rasio Keuangan'!$F$53:$F$72,9) -> 0.3673 | C37: =(9-1)/20 -> 0.4 | D37: =9/20 -> 0.45 | E37: =NORMDIST(B37,$J28,$J29,TRUE()) -> 0.55272179 | F37: =ABS(D37-E37) -> 0.10272179 | G37: =ABS(E37-C37) -> 0.15272179
A38: 10 | B38: =SMALL('Data Rasio Keuangan'!$F$53:$F$72,10) -> 0.3731 | C38: =(10-1)/20 -> 0.45 | D38: =10/20 -> 0.5 | E38: =NORMDIST(B38,$J28,$J29,TRUE()) -> 0.5580007 | F38: =ABS(D38-E38) -> 0.058000696 | G38: =ABS(E38-C38) -> 0.1080007
A39: 11 | B39: =SMALL('Data Rasio Keuangan'!$F$53:$F$72,11) -> 0.4375 | C39: =(11-1)/20 -> 0.5 | D39: =11/20 -> 0.55 | E39: =NORMDIST(B39,$J28,$J29,TRUE()) -> 0.61571953 | F39: =ABS(D39-E39) -> 0.065719528 | G39: =ABS(E39-C39) -> 0.11571953
A40: 12 | B40: =SMALL('Data Rasio Keuangan'!$F$53:$F$72,12) -> 0.438 | C40: =(12-1)/20 -> 0.55 | D40: =12/20 -> 0.6 | E40: =NORMDIST(B40,$J28,$J29,TRUE()) -> 0.6161595 | F40: =ABS(D40-E40) -> 0.016159497 | G40: =ABS(E40-C40) -> 0.066159497
A41: 13 | B41: =SMALL('Data Rasio Keuangan'!$F$53:$F$72,13) -> 0.4428 | C41: =(13-1)/20 -> 0.6 | D41: =13/20 -> 0.65 | E41: =NORMDIST(B41,$J28,$J29,TRUE()) -> 0.62037551 | F41: =ABS(D41-E41) -> 0.029624493 | G41: =ABS(E41-C41) -> 0.020375507
...

Sheet ANOMV
A1: Uji Homogenitas Variansi — Prosedur ANOMV (Periode 2021-2025)
A3: I (jumlah kelompok) | B3: 5
A4: n (observasi/kelompok) | B4: 4
A5: N = I x n | B5: =B3*B4 -> 20
A6: alpha | B6: 0.05
A7: vi = n-1 | B7: =B4-1 -> 3
A8: ve = N-I | B8: =B5-B3 -> 15
A9: alpha/(2I) | B9: =B6/(2*B3) -> 0.005
A11: UDLv = F(alpha/(2I); vi,ve) | B11: =FINV(B9,B7,B8) -> 6.476039
A12: LDLv = 1 / F(alpha/(2I); ve,vi) | B12: =1/FINV(B9,B8,B7) -> 0.023210118
A14: Variansi Kelompok (si^2)
A15: Kelompok (i) | B15: Tahun | C15: n | D15: ROIC | E15: ROA | F15: ROE | G15: NPM | H15: DER | I15: TDTC | J15: CR | K15: FAT
A16: 1 | B16: 2021 | C16: 4 | D16: =VAR('Data Rasio Keuangan'!E53:E56) -> 0.045266029 | E16: =VAR('Data Rasio Keuangan'!F53:F56) -> 0.0080344092 | F16: =VAR('Data Rasio Keuangan'!G53:G56) -> 0.087878297 | G16: =VAR('Data Rasio Keuangan'!H53:H56) -> 0.7413807 | H16: =VAR('Data Rasio Keuangan'!I53:I56) -> 19.139293 | I16: =VAR('Data Rasio Keuangan'!J53:J56) -> 0.35663339 | J16: =VAR('Data Rasio Keuangan'!K53:K56) -> 0.00090283667 | K16: =VAR('Data Rasio Keuangan'!L53:L56) -> 9.6291667e-06
A17: 2 | B17: 2022 | C17: 4 | D17: =VAR('Data Rasio Keuangan'!E57:E60) -> 0.41722047 | E17: =VAR('Data Rasio Keuangan'!F57:F60) -> 0.083846303 | F17: =VAR('Data Rasio Keuangan'!G57:G60) -> 1.103986 | G17: =VAR('Data Rasio Keuangan'!H57:H60) -> 10.280006 | H17: =VAR('Data Rasio Keuangan'!I57:I60) -> 382.86506 | I17: =VAR('Data Rasio Keuangan'!J57:J60) -> 5.3176502 | J17: =VAR('Data Rasio Keuangan'!K57:K60) -> 0.0037881892 | K17: =VAR('Data Rasio Keuangan'!L57:L60) -> 5.14425e-05
A18: 3 | B18: 2023 | C18: 4 | D18: =VAR('Data Rasio Keuangan'!E61:E64) -> 0.021831229 | E18: =VAR('Data Rasio Keuangan'!F61:F64) -> 0.028515463 | F18: =VAR('Data Rasio Keuangan'!G61:G64) -> 0.31087137 | G18: =VAR('Data Rasio Keuangan'!H61:H64) -> 3.1980597 | H18: =VAR('Data Rasio Keuangan'!I61:I64) -> 47.655255 | I18: =VAR('Data Rasio Keuangan'!J61:J64) -> 0.96615763 | J18: =VAR('Data Rasio Keuangan'!K61:K64) -> 0.0024535892 | K18: =VAR('Data Rasio Keuangan'!L61:L64) -> 1.5435833e-05
A19: 4 | B19: 2024 | C19: 4 | D19: =VAR('Data Rasio Keuangan'!E65:E68) -> 0.07344145 | E19: =VAR('Data Rasio Keuangan'!F65:F68) -> 0.0255325 | F19: =VAR('Data Rasio Keuangan'!G65:G68) -> 0.26716104 | G19: =VAR('Data Rasio Keuangan'!H65:H68) -> 2.165666 | H19: =VAR('Data Rasio Keuangan'!I65:I68) -> 32.865811 | I19: =VAR('Data Rasio Keuangan'!J65:J68) -> 0.57384463 | J19: =VAR('Data Rasio Keuangan'!K65:K68) -> 0.00092125333 | K19: =VAR('Data Rasio Keuangan'!L65:L68) -> 4.1989167e-05
A20: 5 | B20: 2025 | C20: 4 | D20: =VAR('Data Rasio Keuangan'!E69:E72) -> 0.39413934 | E20: =VAR('Data Rasio Keuangan'!F69:F72) -> 0.79082478 | F20: =VAR('Data Rasio Keuangan'!G69:G72) -> 11.076187 | G20: =VAR('Data Rasio Keuangan'!H69:H72) -> 99.338875 | H20: =VAR('Data Rasio Keuangan'!I69:I72) -> 188.55805 | I20: =VAR('Data Rasio Keuangan'!J69:J72) -> 2.5712648 | J20: =VAR('Data Rasio Keuangan'!K69:K72) -> 0.0069733367 | K20: =VAR('Data Rasio Keuangan'!L69:L72) -> 0.00016262917
A21: SSE = Sum(n-1)si^2 | D21: =3*SUM(D16:D20) -> 2.8556955 | E21: =3*SUM(E16:E20) -> 2.8102604 | F21: =3*SUM(F16:F20) -> 38.538252 | G21: =3*SUM(G16:G20) -> 347.17196 | H21: =3*SUM(H16:H20) -> 2013.2504 | I21: =3*SUM(I16:I20) -> 29.356652 | J21: =3*SUM(J16:J20) -> 0.045117615 | K21: =3*SUM(K16:K20) -> 0.0008433775
A22: MSE = SSE/(N-I) | D22: =D21/$B$8 -> 0.1903797 | E22: =E21/$B$8 -> 0.18735069 | F22: =F21/$B$8 -> 2.5692168 | G22: =G21/$B$8 -> 23.144798 | H22: =H21/$B$8 -> 134.21669 | I22: =I21/$B$8 -> 1.9571101 | J22: =J21/$B$8 -> 0.003007841 | K22: =K21/$B$8 -> 5.6225167e-05
A24: Statistik Uji Fi = MSE / si^2
A25: Kelompok (i) | B25: Tahun | D25: ROIC | E25: ROA | F25: ROE | G25: NPM | H25: DER | I25: TDTC | J25: CR | K25: FAT
A26: 1 | B26: 2021 | D26: =D16/D$22 -> 0.2377671 | E26: =E16/E$22 -> 0.042884332 | F26: =F16/F$22 -> 0.034204313 | G26: =G16/G$22 -> 0.032032283 | H26: =H16/H$22 -> 0.14259994 | I26: =I16/I$22 -> 0.18222449 | J26: =J16/J$22 -> 0.30016103 | K26: =K16/K$22 -> 0.17126079
A27: 2 | B27: 2022 | D27: =D17/D$22 -> 2.1915176 | E27: =E17/E$22 -> 0.44753666 | F27: =F17/F$22 -> 0.42969748 | G27: =G17/G$22 -> 0.44416054 | H27: =H17/H$22 -> 2.852589 | I27: =I17/I$22 -> 2.717093 | J27: =J17/J$22 -> 1.259438 | K27: =K17/K$22 -> 0.91493726
A28: 3 | B28: 2023 | D28: =D18/D$22 -> 0.11467204 | E28: =E18/E$22 -> 0.15220367 | F28: =F18/F$22 -> 0.12099849 | G28: =G18/G$22 -> 0.13817618 | H28: =H18/H$22 -> 0.35506206 | I28: =I18/I$22 -> 0.49366544 | J28: =J18/J$22 -> 0.81573101 | K28: =K18/K$22 -> 0.27453602
A29: 4 | B29: 2024 | D29: =D19/D$22 -> 0.38576303 | E29: =E19/E$22 -> 0.13628186 | F29: =F19/F$22 -> 0.1039854 | G29: =G19/G$22 -> 0.093570317 | H29: =H19/H$22 -> 0.24487126 | I29: =I19/I$22 -> 0.29321019 | J29: =J19/J$22 -> 0.30628392 | K29: =K19/K$22 -> 0.74680377
A30: 5 | B30: 2025 | D30: =D20/D$22 -> 2.0702802 | E30: =E20/E$22 -> 4.2210935 | F30: =F20/F$22 -> 4.3111143 | G30: =G20/G$22 -> 4.2920607 | H30: =H20/H$22 -> 1.4048778 | I30: =I20/I$22 -> 1.3138069 | J30: =J20/J$22 -> 2.3183861 | K30: =K20/K$22 -> 2.8924622
A32: Keputusan (LDLv <= Fi <= UDLv)
A33: Kelompok (i) | B33: Tahun | D33: ROIC | E33: ROA | F33: ROE | G33: NPM | H33: DER | I33: TDTC | J33: CR | K33: FAT
A34: 1 | B34: 2021 | D34: =IF(AND(D26>=$B$12,D26<=$B$11),"Homogen","Menyimpang") -> Homogen | E34: =IF(AND(E26>=$B$12,E26<=$B$11),"Homogen","Menyimpang") -> Homogen | F34: =IF(AND(F26>=$B$12,F26<=$B$11),"Homogen","Menyimpang") -> Homogen | G34: =IF(AND(G26>=$B$12,G26<=$B$11),"Homogen","Menyimpang") -> Homogen | H34: =IF(AND(H26>=$B$12,H26<=$B$11),"Homogen","Menyimpang") -> Homogen | I34: =IF(AND(I26>=$B$12,I26<=$B$11),"Homogen","Menyimpang") -> Homogen | J34: =IF(AND(J26>=$B$12,J26<=$B$11),"Homogen","Menyimpang") -> Homogen | K34: =IF(AND(K26>=$B$12,K26<=$B$11),"Homogen","Menyimpang") -> Homogen
A35: 2 | B35: 2022 | D35: =IF(AND(D27>=$B$12,D27<=$B$11),"Homogen","Menyimpang") -> Homogen | E35: =IF(AND(E27>=$B$12,E27<=$B$11),"Homogen","Menyimpang") -> Homogen | F35: =IF(AND(F27>=$B$12,F27<=$B$11),"Homogen","Menyimpang") -> Homogen | G35: =IF(AND(G27>=$B$12,G27<=$B$11),"Homogen","Menyimpang") -> Homogen | H35: =IF(AND(H27>=$B$12,H27<=$B$11),"Homogen","Menyimpang") -> Homogen | I35: =IF(AND(I27>=$B$12,I27<=$B$11),"Homogen","Menyimpang") -> Homogen | J35: =IF(AND(J27>=$B$12,J27<=$B$11),"Homogen","Menyimpang") -> Homogen | K35: =IF(AND(K27>=$B$12,K27<=$B$11),"Homogen","Menyimpang") -> Homogen
A36: 3 | B36: 2023 | D36: =IF(AND(D28>=$B$12,D28<=$B$11),"Homogen","Menyimpang") -> Homogen | E36: =IF(AND(E28>=$B$12,E28<=$B$11),"Homogen","Menyimpang") -> Homogen | F36: =IF(AND(F28>=$B$12,F28<=$B$11),"Homogen","Menyimpang") -> Homogen | G36: =IF(AND(G28>=$B$12,G28<=$B$11),"Homogen","Menyimpang") -> Homogen | H36: =IF(AND(H28>=$B$12,H28<=$B$11),"Homogen","Menyimpang") -> Homogen | I36: =IF(AND(I28>=$B$12,I28<=$B$11),"Homogen","Menyimpang") -> Homogen | J36: =IF(AND(J28>=$B$12,J28<=$B$11),"Homogen","Menyimpang") -> Homogen | K36: =IF(AND(K28>=$B$12,K28<=$B$11),"Homogen","Menyimpang") -> Homogen
A37: 4 | B37: 2024 | D37: =IF(AND(D29>=$B$12,D29<=$B$11),"Homogen","Menyimpang") -> Homogen | E37: =IF(AND(E29>=$B$12,E29<=$B$11),"Homogen","Menyimpang") -> Homogen | F37: =IF(AND(F29>=$B$12,F29<=$B$11),"Homogen","Menyimpang") -> Homogen | G37: =IF(AND(G29>=$B$12,G29<=$B$11),"Homogen","Menyimpang") -> Homogen | H37: =IF(AND(H29>=$B$12,H29<=$B$11),"Homogen","Menyimpang") -> Homogen | I37: =IF(AND(I29>=$B$12,I29<=$B$11),"Homogen","Menyimpang") -> Homogen | J37: =IF(AND(J29>=$B$12,J29<=$B$11),"Homogen","Menyimpang") -> Homogen | K37: =IF(AND(K29>=$B$12,K29<=$B$11),"Homogen","Menyimpang") -> Homogen
A38: 5 | B38: 2025 | D38: =IF(AND(D30>=$B$12,D30<=$B$11),"Homogen","Menyimpang") -> Homogen | E38: =IF(AND(E30>=$B$12,E30<=$B$11),"Homogen","Menyimpang") -> Homogen | F38: =IF(AND(F30>=$B$12,F30<=$B$11),"Homogen","Menyimpang") -> Homogen | G38: =IF(AND(G30>=$B$12,G30<=$B$11),"Homogen","Menyimpang") -> Homogen | H38: =IF(AND(H30>=$B$12,H30<=$B$11),"Homogen","Menyimpang") -> Homogen | I38: =IF(AND(I30>=$B$12,I30<=$B$11),"Homogen","Menyimpang") -> Homogen | J38: =IF(AND(J30>=$B$12,J30<=$B$11),"Homogen","Menyimpang") -> Homogen | K38: =IF(AND(K30>=$B$12,K30<=$B$11),"Homogen","Menyimpang") -> Homogen
A40: Kesimpulan Homogenitas per Rasio | D40: =IF(COUNTIF(D34:D38,"Menyimpang")=0,"Homogen (H0 gagal ditolak)","Tidak Homogen (H0 ditolak)") -> Homogen (H0 gagal ditolak) | E40: =IF(COUNTIF(E34:E38,"Menyimpang")=0,"Homogen (H0 gagal ditolak)","Tidak Homogen (H0 ditolak)") -> Homogen (H0 gagal ditolak) | F40: =IF(COUNTIF(F34:F38,"Menyimpang")=0,"Homogen (H0 gagal ditolak)","Tidak Homogen (H0 ditolak)") -> Homogen (H0 gagal ditolak) | G40: =IF(COUNTIF(G34:G38,"Menyimpang")=0,"Homogen (H0 gagal ditolak)","Tidak Homogen (H0 ditolak)") -> Homogen (H0 gagal ditolak) | H40: =IF(COUNTIF(H34:H38,"Menyimpang")=0,"Homogen (H0 gagal ditolak)","Tidak Homogen (H0 ditolak)") -> Homogen (H0 gagal ditolak) | I40: =IF(COUNTIF(I34:I38,"Menyimpang")=0,"Homogen (H0 gagal ditolak)","Tidak Homogen (H0 ditolak)") -> Homogen (H0 gagal ditolak) | J40: =IF(COUNTIF(J34:J38,"Menyimpang")=0,"Homogen (H0 gagal ditolak)","Tidak Homogen (H0 ditolak)") -> Homogen (H0 gagal ditolak) | K40: =IF(COUNTIF(K34:K38,"Menyimpang")=0,"Homogen (H0 gagal ditolak)","Tidak Homogen (H0 ditolak)") -> Homogen (H0 gagal ditolak)

Sheet Analisis ANOM
A1: Analisis ANOM Kinerja Keuangan
A3: Analisis ANOM - ROIC
A4: Kelompok (i) | B4: Tahun | C4: Rata-rata Kelompok (ȳᵢ.) | D4: Dᵢ = ȳᵢ. - ȳ.. | E4: Status | G4: Grand Mean (ȳ..) | H4: ='Data Rasio Keuangan'!E82 -> 1.09211
A5: 1 | B5: 2021 | C5: ='Data Rasio Keuangan'!E77 -> 1.178325 | D5: =C5-$H$4 -> 0.086215 | E5: =IF(H9="","Menunggu nilai h",IF(C5>$H$10,"Signifikan tinggi (>UDL)",IF(C5<$H$11,"Signifikan rendah (<LDL)","Dalam batas (tidak signifikan)"))) -> Dalam batas (tidak signifikan) | G5: MSE | H5: =ANOMV!D$22 -> 0.1903797
A6: 2 | B6: 2022 | C6: ='Data Rasio Keuangan'!E78 -> 0.899075 | D6: =C6-$H$4 -> -0.193035 | E6: =IF(H9="","Menunggu nilai h",IF(C6>$H$10,"Signifikan tinggi (>UDL)",IF(C6<$H$11,"Signifikan rendah (<LDL)","Dalam batas (tidak signifikan)"))) -> Dalam batas (tidak signifikan) | G6: I | H6: 5
A7: 3 | B7: 2023 | C7: ='Data Rasio Keuangan'!E79 -> 1.208875 | D7: =C7-$H$4 -> 0.116765 | E7: =IF(H9="","Menunggu nilai h",IF(C7>$H$10,"Signifikan tinggi (>UDL)",IF(C7<$H$11,"Signifikan rendah (<LDL)","Dalam batas (tidak signifikan)"))) -> Dalam batas (tidak signifikan) | G7: N | H7: 20
A8: 4 | B8: 2024 | C8: ='Data Rasio Keuangan'!E80 -> 1.29325 | D8: =C8-$H$4 -> 0.20114 | E8: =IF(H9="","Menunggu nilai h",IF(C8>$H$10,"Signifikan tinggi (>UDL)",IF(C8<$H$11,"Signifikan rendah (<LDL)","Dalam batas (tidak signifikan)"))) -> Dalam batas (tidak signifikan) | G8: SE(Dᵢ) = sqrt(MSE*(I-1)/N) | H8: =SQRT(H5*(H6-1)/H7) -> 0.19513057
A9: 5 | B9: 2025 | C9: ='Data Rasio Keuangan'!E81 -> 0.881025 | D9: =C9-$H$4 -> -0.211085 | E9: =IF(H9="","Menunggu nilai h",IF(C9>$H$10,"Signifikan tinggi (>UDL)",IF(C9<$H$11,"Signifikan rendah (<LDL)","Dalam batas (tidak signifikan)"))) -> Dalam batas (tidak signifikan) | G9: h(0,05;5;15) <-- ISI DI SINI | H9: 2.88
G10: UDL = ȳ.. + h*SE(Dᵢ) | H10: =H4+H9*H8 -> 1.6540861
G11: LDL = ȳ.. - h*SE(Dᵢ) | H11: =H4-H9*H8 -> 0.53013395
A12: Analisis ANOM - ROA
A13: Kelompok (i) | B13: Tahun | C13: Rata-rata Kelompok (ȳᵢ.) | D13: Dᵢ = ȳᵢ. - ȳ.. | E13: Status | G13: Grand Mean (ȳ..) | H13: ='Data Rasio Keuangan'!F82 -> 0.309765
A14: 1 | B14: 2021 | C14: ='Data Rasio Keuangan'!F77 -> 0.470775 | D14: =C14-$H$13 -> 0.16101 | E14: =IF(H18="","Menunggu nilai h",IF(C14>$H$19,"Signifikan tinggi (>UDL)",IF(C14<$H$20,"Signifikan rendah (<LDL)","Dalam batas (tidak signifikan)"))) -> Dalam batas (tidak signifikan) | G14: MSE | H14: =ANOMV!E$22 -> 0.18735069
A15: 2 | B15: 2022 | C15: ='Data Rasio Keuangan'!F78 -> 0.343125 | D15: =C15-$H$13 -> 0.03336 | E15: =IF(H18="","Menunggu nilai h",IF(C15>$H$19,"Signifikan tinggi (>UDL)",IF(C15<$H$20,"Signifikan rendah (<LDL)","Dalam batas (tidak signifikan)"))) -> Dalam batas (tidak signifikan) | G15: I | H15: 5
A16: 3 | B16: 2023 | C16: ='Data Rasio Keuangan'!F79 -> 0.334225 | D16: =C16-$H$13 -> 0.02446 | E16: =IF(H18="","Menunggu nilai h",IF(C16>$H$19,"Signifikan tinggi (>UDL)",IF(C16<$H$20,"Signifikan rendah (<LDL)","Dalam batas (tidak signifikan)"))) -> Dalam batas (tidak signifikan) | G16: N | H16: 20
A17: 4 | B17: 2024 | C17: ='Data Rasio Keuangan'!F80 -> 0.4658 | D17: =C17-$H$13 -> 0.156035 | E17: =IF(H18="","Menunggu nilai h",IF(C17>$H$19,"Signifikan tinggi (>UDL)",IF(C17<$H$20,"Signifikan rendah (<LDL)","Dalam batas (tidak signifikan)"))) -> Dalam batas (tidak signifikan) | G17: SE(Dᵢ) = sqrt(MSE*(I-1)/N) | H17: =SQRT(H14*(H15-1)/H16) -> 0.19357205
A18: 5 | B18: 2025 | C18: ='Data Rasio Keuangan'!F81 -> -0.0651 | D18: =C18-$H$13 -> -0.374865 | E18: =IF(H18="","Menunggu nilai h",IF(C18>$H$19,"Signifikan tinggi (>UDL)",IF(C18<$H$20,"Signifikan rendah (<LDL)","Dalam batas (tidak signifikan)"))) -> Dalam batas (tidak signifikan) | G18: h(0,05;5;15) <-- ISI DI SINI | H18: 2.88
G19: UDL = ȳ.. + h*SE(Dᵢ) | H19: =H13+H18*H17 -> 0.8672525
G20: LDL = ȳ.. - h*SE(Dᵢ) | H20: =H13-H18*H17 -> -0.2477225
A21: Analisis ANOM - ROE
A22: Kelompok (i) | B22: Tahun | C22: Rata-rata Kelompok (ȳᵢ.) | D22: Dᵢ = ȳᵢ. - ȳ.. | E22: Status | G22: Grand Mean (ȳ..) | H22: ='Data Rasio Keuangan'!G82 -> 1.02882
A23: 1 | B23: 2021 | C23: ='Data Rasio Keuangan'!G77 -> 1.63965 | D23: =C23-$H$22 -> 0.61083 | E23: =IF(H27="","Menunggu nilai h",IF(C23>$H$28,"Signifikan tinggi (>UDL)",IF(C23<$H$29,"Signifikan rendah (<LDL)","Dalam batas (tidak signifikan)"))) -> Dalam batas (tidak signifikan) | G23: MSE | H23: =ANOMV!F$22 -> 2.5692168
A24: 2 | B24: 2022 | C24: ='Data Rasio Keuangan'!G78 -> 1.2292 | D24: =C24-$H$22 -> 0.20038 | E24: =IF(H27="","Menunggu nilai h",IF(C24>$H$28,"Signifikan tinggi (>UDL)",IF(C24<$H$29,"Signifikan rendah (<LDL)","Dalam batas (tidak signifikan)"))) -> Dalam batas (tidak signifikan) | G24: I | H24: 5
A25: 3 | B25: 2023 | C25: ='Data Rasio Keuangan'!G79 -> 1.0926 | D25: =C25-$H$22 -> 0.06378 | E25: =IF(H27="","Menunggu nilai h",IF(C25>$H$28,"Signifikan tinggi (>UDL)",IF(C25<$H$29,"Signifikan rendah (<LDL)","Dalam batas (tidak signifikan)"))) -> Dalam batas (tidak signifikan) | G25: N | H25: 20
A26: 4 | B26: 2024 | C26: ='Data Rasio Keuangan'!G80 -> 1.56105 | D26: =C26-$H$22 -> 0.53223 | E26: =IF(H27="","Menunggu nilai h",IF(C26>$H$28,"Signifikan tinggi (>UDL)",IF(C26<$H$29,"Signifikan rendah (<LDL)","Dalam batas (tidak signifikan)"))) -> Dalam batas (tidak signifikan) | G26: SE(Dᵢ) = sqrt(MSE*(I-1)/N) | H26: =SQRT(H23*(H24-1)/H25) -> 0.71682868
A27: 5 | B27: 2025 | C27: ='Data Rasio Keuangan'!G81 -> -0.3784 | D27: =C27-$H$22 -> -1.40722 | E27: =IF(H27="","Menunggu nilai h",IF(C27>$H$28,"Signifikan tinggi (>UDL)",IF(C27<$H$29,"Signifikan rendah (<LDL)","Dalam batas (tidak signifikan)"))) -> Dalam batas (tidak signifikan) | G27: h(0,05;5;15) <-- ISI DI SINI | H27: 2.88
G28: UDL = ȳ.. + h*SE(Dᵢ) | H28: =H22+H27*H26 -> 3.0932866
G29: LDL = ȳ.. - h*SE(Dᵢ) | H29: =H22-H27*H26 -> -1.0356466
A30: Analisis ANOM - NPM
A31: Kelompok (i) | B31: Tahun | C31: Rata-rata Kelompok (ȳᵢ.) | D31: Dᵢ = ȳᵢ. - ȳ.. | E31: Status | G31: Grand Mean (ȳ..) | H31: ='Data Rasio Keuangan'!H82 -> 3.34547
A32: 1 | B32: 2021 | C32: ='Data Rasio Keuangan'!H77 -> 4.82695 | D32: =C32-$H$31 -> 1.48148 | E32: =IF(H36="","Menunggu nilai h",IF(C32>$H$37,"Signifikan tinggi (>UDL)",IF(C32<$H$38,"Signifikan rendah (<LDL)","Dalam batas (tidak signifikan)"))) -> Dalam batas (tidak signifikan) | G32: MSE | H32: =ANOMV!G$22 -> 23.144798
A33: 2 | B33: 2022 | C33: ='Data Rasio Keuangan'!H78 -> 3.7909 | D33: =C33-$H$31 -> 0.44543 | E33: =IF(H36="","Menunggu nilai h",IF(C33>$H$37,"Signifikan tinggi (>UDL)",IF(C33<$H$38,"Signifikan rendah (<LDL)","Dalam batas (tidak signifikan)"))) -> Dalam batas (tidak signifikan) | G33: I | H33: 5
A34: 3 | B34: 2023 | C34: ='Data Rasio Keuangan'!H79 -> 3.675525 | D34: =C34-$H$31 -> 0.330055 | E34: =IF(H36="","Menunggu nilai h",IF(C34>$H$37,"Signifikan tinggi (>UDL)",IF(C34<$H$38,"Signifikan rendah (<LDL)","Dalam batas (tidak signifikan)"))) -> Dalam batas (tidak signifikan) | G34: N | H34: 20
A35: 4 | B35: 2024 | C35: ='Data Rasio Keuangan'!H80 -> 4.8846 | D35: =C35-$H$31 -> 1.53913 | E35: =IF(H36="","Menunggu nilai h",IF(C35>$H$37,"Signifikan tinggi (>UDL)",IF(C35<$H$38,"Signifikan rendah (<LDL)","Dalam batas (tidak signifikan)"))) -> Dalam batas (tidak signifikan) | G35: SE(Dᵢ) = sqrt(MSE*(I-1)/N) | H35: =SQRT(H32*(H33-1)/H34) -> 2.1515017
A36: 5 | B36: 2025 | C36: ='Data Rasio Keuangan'!H81 -> -0.450625 | D36: =C36-$H$31 -> -3.796095 | E36: =IF(H36="","Menunggu nilai h",IF(C36>$H$37,"Signifikan tinggi (>UDL)",IF(C36<$H$38,"Signifikan rendah (<LDL)","Dalam batas (tidak signifikan)"))) -> Dalam batas (tidak signifikan) | G36: h(0,05;5;15) <-- ISI DI SINI | H36: 2.88
G37: UDL = ȳ.. + h*SE(Dᵢ) | H37: =H31+H36*H35 -> 9.5417949
G38: LDL = ȳ.. - h*SE(Dᵢ) | H38: =H31-H36*H35 -> -2.8508549
A39: Analisis ANOM - DER
A40: Kelompok (i) | B40: Tahun | C40: Rata-rata Kelompok (ȳᵢ.) | D40: Dᵢ = ȳᵢ. - ȳ.. | E40: Status | G40: Grand Mean (ȳ..) | H40: ='Data Rasio Keuangan'!I82 -> 178.279
A41: 1 | B41: 2021 | C41: ='Data Rasio Keuangan'!I77 -> 170.85537 | D41: =C41-$H$40 -> -7.42363 | E41: =IF(H45="","Menunggu nilai h",IF(C41>$H$46,"Signifikan tinggi (>UDL)",IF(C41<$H$47,"Signifikan rendah (<LDL)","Dalam batas (tidak signifikan)"))) -> Dalam batas (tidak signifikan) | G41: MSE | H41: =ANOMV!H$22 -> 134.21669
...
